<mujoco model="upkie">
    <compiler angle="radian" meshdir="meshes/" autolimits="true"/>

    <worldbody>
        <body name="trunk">
            <site name="imu" size="0.01" pos="0.0 0.0 0.0"/>

            <joint name="world_joint" type="free" limited="false" actuatorfrclimited="false"/>
            <geom size="0.0625 0.085 0.125" pos="0 0 -0.1" type="box" rgba="0.93 0.64 0.52 0.8"/>
            <geom size="0.065 0.037 0.0275" pos="-0.04 0 -0.1" quat="0.5 0.5 0.5 0.5" type="box" rgba="0.3 0.3 0.3 1"/>
            <geom size="0.06 0.035 0.02" pos="0 0 0.045" quat="0.707107 0 0 -0.707107" type="box"
                rgba="0.93 0.64 0.52 1"/>
            <geom size="0.05 0.015" pos="0 0.1 -0.164" quat="0.707107 -0.707107 0 0" type="cylinder"
                rgba="0.1 0.1 0.1 1"/>
            <geom size="0.05 0.015" pos="0 -0.1 -0.164" quat="0 0 0.707107 -0.707107" type="cylinder"
                rgba="0.1 0.1 0.1 1"/>
            <body name="left_femur" pos="0 0.1142 -0.164" quat="0.707107 -0.707107 0 0">
                <inertial pos="0 0.143655 0.0648064" quat="0.410908 0.57546 -0.57546 0.410908" mass="0.69241"
                    diaginertia="0.00305529 0.00296411 0.000644198"/>
                <joint name="left_hip" pos="0 0 0" axis="0 0 -1" range="-1.26 1.26"/>
                <geom size="0.023 0.0025" pos="0 0 -0.0025" type="cylinder" rgba="0.1 0.1 0.1 1"/>
                <geom size="0.025 0.045" pos="0 0 0.025" quat="0.5 -0.5 0.5 0.5" type="cylinder" rgba="0.1 0.1 0.1 1"/>
                <geom size="0.012 0.13" pos="0 0.07 0.025" quat="0.707107 0.707107 0 0" type="cylinder"
                    rgba="1 0.77 0.48 1"/>
                <geom size="0.05 0.03" pos="0 0.168 0.037" quat="0 0.707107 0.707107 0" type="cylinder"
                    rgba="0.93 0.64 0.52 1"/>
                <geom size="0.05 0.015" pos="0 0.168 0.082" type="cylinder" rgba="0.1 0.1 0.1 1"/>
                <body name="left_tibia" pos="0 0.168 0.0962">
                    <inertial pos="0 0.129919 0.000191464" quat="0.773688 0.633567 0 0" mass="0.3954"
                        diaginertia="0.0022225 0.00219783 0.000264492"/>
                    <joint name="left_knee" pos="0 0 0" axis="0 0 -1" range="-2.51 2.51"/>
                    <geom size="0.023 0.0025" pos="0 0 -0.0025" type="cylinder" rgba="0.1 0.1 0.1 1"/>
                    <geom size="0.025 0.045" pos="0 0 0.025" quat="0.5 -0.5 0.5 0.5" type="cylinder"
                        rgba="0.93 0.64 0.52 1"/>
                    <geom size="0.012 0.13" pos="0 0.07 0.025" quat="0 0 0.707107 -0.707107" type="cylinder"
                        rgba="1 0.77 0.48 1"/>
                    <geom size="0.046 0.034 0.028" pos="0 0.173 0.0185" quat="0 0 0 -1" type="box"
                        rgba="0.65 0.76 0.91 1"/>
                    <geom size="0.045 0.023 0.002" pos="0 0.175 -0.0105" quat="0 0 0 -1" type="box" rgba="0.8 0.8 0.8 1"/>
                    <geom size="0.03 0.009" pos="0 0.175 -0.022" quat="0 0 -1 0" type="cylinder" rgba="0.22 0.22 0.25 1"/>
                    <body name="left_foot" pos="0 0.175 -0.012" quat="0 0 -1 0">
                        <site name="left_foot" rgba="1 0 0 1" pos="0.0 0.0 0.0"/>
                        <inertial pos="0 0.000254674 0.0355348" quat="0.497084 0.502899 -0.502899 0.497084"
                            mass="0.18455" diaginertia="0.000174567 0.000134472 0.000132269"/>
                        <joint name="left_wheel" pos="0 0 0" axis="0 0 -1"/>
                        <geom size="0.034 0.008" pos="0 0 0.015" type="cylinder" rgba="0.5 0.55 0.6 1"/>
                        <geom size="0.039 0.0125" pos="0 0 0.0376" type="cylinder" rgba="0.93 0.64 0.52 1"/>
                        <geom size="0.05 0.02" pos="0 0 0.046" type="cylinder" rgba="0.3 0.3 0.3 1"/>
                    </body>
                </body>
            </body>
            <body name="right_femur" pos="0 -0.1142 -0.164" quat="0 0 0.707107 -0.707107">
                <inertial pos="0 0.143655 0.0648064" quat="0.410908 0.57546 -0.57546 0.410908" mass="0.69241"
                    diaginertia="0.00305529 0.00296411 0.000644198"/>
                <joint name="right_hip" pos="0 0 0" axis="0 0 -1" range="-1.26 1.26"/>
                <geom size="0.023 0.0025" pos="0 0 -0.0025" type="cylinder" rgba="0.1 0.1 0.1 1"/>
                <geom size="0.025 0.045" pos="0 0 0.025" quat="0.5 -0.5 0.5 0.5" type="cylinder" rgba="0.1 0.1 0.1 1"/>
                <geom size="0.012 0.13" pos="0 0.07 0.025" quat="0.707107 0.707107 0 0" type="cylinder"
                    rgba="1 0.77 0.48 1"/>
                <geom size="0.05 0.03" pos="0 0.168 0.037" quat="0 0.707107 0.707107 0" type="cylinder"
                    rgba="0.93 0.64 0.52 1"/>
                <geom size="0.05 0.015" pos="0 0.168 0.082" type="cylinder" rgba="0.1 0.1 0.1 1"/>
                <body name="right_tibia" pos="0 0.168 0.0962">
                    <inertial pos="0 0.129919 0.000196523" quat="0.77365 0.633613 0 0" mass="0.3954"
                        diaginertia="0.00222226 0.00219775 0.000264334"/>
                    <joint name="right_knee" pos="0 0 0" axis="0 0 -1" range="-2.51 2.51"/>
                    <geom size="0.023 0.0025" pos="0 0 -0.0025" type="cylinder" rgba="0.1 0.1 0.1 1"/>
                    <geom size="0.025 0.045" pos="0 0 0.025" quat="0.5 -0.5 0.5 0.5" type="cylinder"
                        rgba="0.93 0.64 0.52 1"/>
                    <geom size="0.012 0.13" pos="0 0.07 0.025" quat="0 0 0.707107 -0.707107" type="cylinder"
                        rgba="1 0.77 0.48 1"/>
                    <geom size="0.046 0.034 0.028" pos="0 0.173 0.0185" quat="0 0 0 -1" type="box"
                        rgba="0.65 0.76 0.91 1"/>
                    <geom size="0.045 0.023 0.002" pos="0 0.175 -0.0105" quat="0 0 0 -1" type="box" rgba="0.8 0.8 0.8 1"/>
                    <geom size="0.03 0.009" pos="0 0.175 -0.022" quat="0 0 -1 0" type="cylinder" rgba="0.22 0.22 0.25 1"/>
                    <body name="right_foot" pos="0 0.175 -0.012" quat="0 0 -1 0">
                        <site name="right_foot" rgba="1 0 0 1" pos="0.0 0.0 0.0"/>
                        <inertial pos="0 0.000254674 0.0355348" quat="0.497084 0.502899 -0.502899 0.497084"
                            mass="0.18455" diaginertia="0.000174567 0.000134472 0.000132269"/>
                        <joint name="right_wheel" pos="0 0 0" axis="0 0 -1"/>
                        <geom size="0.034 0.008" pos="0 0 0.015" type="cylinder" rgba="0.5 0.55 0.6 1"/>
                        <geom size="0.039 0.0125" pos="0 0 0.0376" type="cylinder" rgba="0.93 0.64 0.52 1"/>
                        <geom size="0.05 0.02" pos="0 0 0.046" type="cylinder" rgba="0.3 0.3 0.3 1"/>
                    </body>
                </body>
            </body>
        </body>
    </worldbody>

    <actuator>
        <position joint="left_hip" name="left_hip" kp="1" kv="0.1" ctrlrange="-1.26 1.26" forcerange="-16 16"/>
        <position joint="left_knee" name="left_knee" kp="1" kv="0.1" ctrlrange="-2.51 2.51" forcerange="-16 16"/>
        <velocity joint="left_wheel" name="left_wheel" kv="5" forcerange="-1.7 1.7"/>

        <position joint="right_hip" name="right_hip" kp="1" kv="0.1" ctrlrange="-1.26 1.26" forcerange="-16 16"/>
        <position joint="right_knee" name="right_knee" kp="1" kv="0.1" ctrlrange="-2.51 2.51" forcerange="-16 16"/>
        <velocity joint="right_wheel" name="right_wheel" kv="5" forcerange="-1.7 1.7"/>
    </actuator>

    <sensor>
        <framequat name="orientation" objtype="site" objname="imu"/>
        <gyro name="imu_ang_vel" site="imu"/>
        <velocimeter name="imu_lin_vel" site="imu"/>
    </sensor>

</mujoco>