<?xml version="1.0" ?>
<!-- Generated using onshape-to-robot -->
<!-- Onshape https://cad.onshape.com/documents/626c0feba56391e940274c5a/w/1443de40ca7efab6f3e18861/e/f40baedc39efd40637593503 -->

<mujoco model="upkie">
  <compiler angle="radian" meshdir="assets" autolimits="true"/>
  <default>
    <default class="upkie">
      <joint frictionloss="0.1" armature="0.005"/>
      <position dampratio="1"/>
      <default class="visual">
        <geom type="mesh" contype="0" conaffinity="0" density="0" group="2"/>
      </default>
      <default class="collision">
        <geom group="3" contype="1" conaffinity="1"/>
      </default>
    </default>
  </default>

  <!-- Additional no_slip.xml -->
  <option noslip_iterations="4"/>
  
  <worldbody>
    <!-- Link trunk -->
    <body name="trunk" pos="0 0 0" quat="1 0 0 0" childclass="upkie">
      <freejoint name="trunk_freejoint"/>
      <inertial pos="0.000135877 0.000596249 0.0877119" mass="2.6415" fullinertia="0.0217792 0.0127537 0.0147651 6.48606e-05 0.000263842 -3.98875e-05"/>
      <!-- Part back_cover -->
      <geom type="mesh" class="visual" pos="-0.0002 -0.085 0.1252" quat="0.707107 8.67097e-16 2.22045e-16 0.707107" mesh="back_cover" material="back_cover_material"/>
      <!-- Part right_side -->
      <geom type="mesh" class="visual" pos="8.57208e-17 -0.085 0.1252" quat="0.707107 8.19486e-16 4.44089e-16 0.707107" mesh="right_side" material="right_side_material"/>
      <!-- Part separating_panel -->
      <geom type="mesh" class="visual" pos="-1.00621e-16 -0.085 0.1248" quat="0.707107 1.61553e-15 6.66134e-16 0.707107" mesh="separating_panel" material="separating_panel_material"/>
      <!-- Part left_side -->
      <geom type="mesh" class="visual" pos="1.02374e-16 -0.085 0.1252" quat="0.707107 8.68551e-16 4.44089e-16 0.707107" mesh="left_side" material="left_side_material"/>
      <!-- Part top_cover -->
      <geom type="mesh" class="visual" pos="-1.15178e-16 -0.085 0.125" quat="0.707107 1.64996e-15 6.66134e-16 0.707107" mesh="top_cover" material="top_cover_material"/>
      <!-- Part power_dist -->
      <geom type="mesh" class="visual" pos="-0.0552 -0.03 0.125246" quat="0.5 0.5 0.5 -0.5" mesh="power_dist" material="power_dist_material"/>
      <!-- Part bottom_cover -->
      <geom name="trunk_collision1" class="collision" pos="5.22993e-17 -2.77556e-17 0.125" quat="0.707107 7.72671e-17 -9.71445e-17 0.707107" type="box" size="0.085 0.0652 0.125"/>
      <geom type="mesh" class="visual" pos="-2.54306e-17 -0.085 0.125" quat="0.707107 7.72671e-17 -9.71445e-17 0.707107" mesh="bottom_cover" material="bottom_cover_material"/>
      <!-- Part switch -->
      <geom type="mesh" class="visual" pos="-0.035 -0.085 0.1572" quat="0.5 0.5 -0.5 0.5" mesh="switch" material="switch_material"/>
      <!-- Part front_opening -->
      <geom type="mesh" class="visual" pos="6.92065e-16 -0.085 0.125" quat="0.707107 1.32681e-15 1.08247e-15 0.707107" mesh="front_opening" material="front_opening_material"/>
      <!-- Part qdd100_stator -->
      <geom name="trunk_collision2" class="collision" pos="1.68912e-16 0.09935 0.0602" quat="0.5 0.5 0.5 -0.5" type="cylinder" size="0.05 0.01435"/>
      <geom type="mesh" class="visual" pos="2.79473e-16 0.085 0.1252" quat="0.707107 -2.93569e-16 9.99201e-16 -0.707107" mesh="qdd100_stator" material="qdd100_stator_material"/>
      <!-- Part back_opening -->
      <geom type="mesh" class="visual" pos="-1.02878e-15 -0.085 0.125" quat="0.707107 1.32681e-15 1.05471e-15 0.707107" mesh="back_opening" material="back_opening_material"/>
      <!-- Part qdd100_stator_2 -->
      <geom name="trunk_collision3" class="collision" pos="-5.90135e-18 -0.09935 0.0602" quat="0.5 -0.5 0.5 0.5" type="cylinder" size="0.05 0.01435"/>
      <geom type="mesh" class="visual" pos="1.6458e-16 -0.085 0.1252" quat="0.707107 1.15914e-15 7.77156e-16 0.707107" mesh="qdd100_stator" material="qdd100_stator_material"/>
      <!-- Part battery_tattu -->
      <geom type="mesh" class="visual" pos="0.011 -0.0225 0.0748" quat="8.88178e-16 -1.4988e-15 -0.707107 -0.707107" mesh="battery_tattu" material="battery_tattu_material"/>
      <!-- Part raspberry -->
      <geom type="mesh" class="visual" pos="-0.0417 0.0400012 0.132746" quat="0.707107 -4.29469e-15 5.32907e-15 -0.707107" mesh="raspberry" material="raspberry_material"/>
      <!-- Part front_cover -->
      <geom type="mesh" class="visual" pos="0.0002 -0.085 0.1252" quat="0.707107 1.30451e-15 2.22045e-16 0.707107" mesh="front_cover" material="front_cover_material"/>
      <!-- Frame body -->
      <site group="0" name="body" pos="0 0 0" quat="1 0 0 0"/>
      <!-- Frame imu -->
      <site group="0" name="imu" pos="-0.04095 0.0400012 0.130246" quat="0.5 -0.5 0.5 -0.5"/>
      <!-- Link femur -->
      <body name="femur" pos="1.88318e-16 0.1137 0.0602" quat="5.55112e-16 -5.01408e-16 -0.707107 -0.707107">
        <!-- Joint from trunk to femur -->
        <joint name="left_hip" type="hinge" range="-3.05433 3.05433"/>
        <inertial pos="-1.9262e-08 -0.142827 0.0596176" mass="0.7645" fullinertia="0.00377771 0.000940238 0.00358651 6.45614e-10 -5.25505e-10 0.000901135"/>
        <!-- Part qdd100_rotor -->
        <geom type="mesh" class="visual" pos="-2.46519e-32 -6.93889e-18 -0.0287" quat="1 0 4.16334e-17 -6.67869e-17" mesh="qdd100_rotor" material="qdd100_rotor_material"/>
        <!-- Part qdd100_support -->
        <geom name="left_femur_collision1" class="collision" pos="-1.71761e-14 -0.17015 0.0557487" quat="4.4964e-15 1.67246e-16 1.44329e-15 -1" type="cylinder" size="0.05 0.0125"/>
        <geom name="left_femur_collision2" class="collision" pos="-1.71706e-14 -0.17015 0.0252487" quat="0.5 -0.5 0.5 0.5" type="cylinder" size="0.02 0.03"/>
        <geom type="mesh" class="visual" pos="-1.71783e-14 -0.17015 0.0682487" quat="4.4964e-15 1.67246e-16 1.44329e-15 -1" mesh="qdd100_support" material="qdd100_support_material"/>
        <!-- Part femur -->
        <geom type="mesh" class="visual" pos="-1.99482e-14 -0.2 0.0261244" quat="0.5 -0.5 -0.5 -0.5" mesh="femur" material="femur_material"/>
        <!-- Part link_end -->
        <geom name="left_femur_collision3" class="collision" pos="-2.52545e-32 -6.93889e-18 0.0247" quat="0.707107 0.707107 0 4.9903e-33" type="cylinder" size="0.021 0.04"/>
        <geom type="mesh" class="visual" pos="-2.46519e-32 -6.93889e-18 -0.0287" quat="1 0 4.16334e-17 -6.67869e-17" mesh="link_end" material="link_end_material"/>
        <!-- Part qdd100_stator_3 -->
        <geom name="left_femur_collision4" class="collision" pos="-1.71809e-14 -0.17015 0.0825987" quat="4.4964e-15 1.67246e-16 1.44329e-15 -1" type="cylinder" size="0.05 0.01435"/>
        <geom type="mesh" class="visual" pos="-1.71783e-14 -0.17015 0.0682487" quat="4.4964e-15 1.67246e-16 1.44329e-15 -1" mesh="qdd100_stator__2" material="qdd100_stator__2_material"/>
        <!-- Link tibia -->
        <body name="tibia" pos="-1.71835e-14 -0.17015 0.0969487" quat="1.11022e-16 -4.53804e-15 1 1.42334e-15">
          <!-- Joint from femur to tibia -->
          <joint name="left_knee" type="hinge" range="-2.705260340591202 2.7052603405912197"/>
          <inertial pos="-5.94135e-06 -0.117367 -0.00307405" mass="0.3865" fullinertia="0.00259272 0.000261473 0.00249172 -1.62499e-07 1.48913e-08 0.000309417"/>
          <!-- Part qdd100_rotor_2 -->
          <geom type="mesh" class="visual" pos="2.08167e-17 -7.77156e-16 0.0287" quat="2.06432e-16 4.70457e-15 -1 3.46945e-17" mesh="qdd100_rotor" material="qdd100_rotor_material"/>
          <!-- Part moteus_controller -->
          <geom type="mesh" class="visual" pos="3.74349e-15 -0.1845 0.0046" quat="0.707107 -0.707107 -2.44249e-14 2.77858e-14" mesh="moteus_controller" material="moteus_controller_material"/>
          <!-- Part mj5208_stator -->
          <geom type="mesh" class="visual" pos="2.68656e-15 -0.1765 0.012" quat="1 -1.48176e-17 5.55112e-17 4.97519e-15" mesh="mj5208_stator" material="mj5208_stator_material"/>
          <!-- Part mj5208_support -->
          <geom name="left_tibia_collision1" class="collision" pos="2.35094e-15 -0.17025 -0.02616" quat="0.707107 -0.707107 -2.44249e-14 2.77858e-14" type="cylinder" size="0.022 0.03025"/>
          <geom name="left_tibia_collision2" class="collision" pos="0.019 -0.17025 0.00774" quat="0.707107 -0.707107 -2.44249e-14 2.77858e-14" type="cylinder" size="0.021 0.03025"/>
          <geom name="left_tibia_collision3" class="collision" pos="-0.019 -0.17025 0.00774" quat="0.707107 -0.707107 -2.44249e-14 2.77858e-14" type="cylinder" size="0.021 0.03025"/>
          <geom type="mesh" class="visual" pos="3.10225e-15 -0.1765 0.03424" quat="0.707107 -0.707107 -2.44249e-14 2.77858e-14" mesh="mj5208_support" material="mj5208_support_material"/>
          <!-- Part tibia -->
          <geom type="mesh" class="visual" pos="3.35448e-15 -0.2 -0.0261244" quat="0.5 -0.5 -0.5 -0.5" mesh="tibia" material="tibia_material"/>
          <!-- Part controller_bracket -->
          <geom type="mesh" class="visual" pos="3.10225e-15 -0.1765 0.03424" quat="0.707107 -0.707107 -2.44249e-14 2.77858e-14" mesh="controller_bracket" material="controller_bracket_material"/>
          <!-- Part link_end_2 -->
          <geom name="left_tibia_collision4" class="collision" pos="-9.63002e-18 -7.89025e-16 -0.0247" quat="3.10862e-15 -3.47368e-15 0.707107 -0.707107" type="cylinder" size="0.021 0.04"/>
          <geom type="mesh" class="visual" pos="2.08167e-17 -7.77156e-16 0.0287" quat="2.06432e-16 4.70457e-15 -1 3.46945e-17" mesh="link_end" material="link_end_material"/>
          <!-- Frame left_foot -->
          <site group="0" name="left_foot" pos="2.68542e-15 -0.1765 0.05095" quat="0.707107 -0.707107 -2.22045e-15 4.44208e-15"/>
          <!-- Link wheel -->
          <body name="wheel" pos="2.69207e-15 -0.1765 0.0195" quat="1.4647e-16 0.997711 0.0676268 1.00696e-16">
            <!-- Joint from tibia to wheel -->
            <joint name="left_wheel"/>
            <inertial pos="-7.85066e-06 4.53426e-06 -0.0252368" mass="0.2585" fullinertia="0.000202065 0.000202069 0.000313606 -7.7265e-09 1.97562e-08 -1.14162e-08"/>
            <!-- Part wheel_hub -->
            <geom type="mesh" class="visual" pos="2.01228e-16 -6.10623e-16 -0.0104" quat="0.707107 0.707107 0 6.87727e-17" mesh="wheel_hub" material="wheel_hub_material"/>
            <!-- Part mj5208_rotor -->
            <geom type="mesh" class="visual" pos="6.93889e-18 0 0.0075" quat="0 1 0 0" mesh="mj5208_rotor" material="mj5208_rotor_material"/>
            <!-- Part tire -->
            <geom name="left_foot_collision" class="collision" pos="4.85723e-16 -3.53884e-16 -0.0312" quat="3.06162e-17 -1 -5.39294e-17 1.45037e-25" type="cylinder" size="0.055 0.022"/>
            <geom type="mesh" class="visual" pos="4.51028e-16 -3.33067e-16 -0.0312" quat="0.707107 0.707107 1.11022e-16 3.81339e-17" mesh="tire" material="tire_material"/>
          </body>
        </body>
      </body>
      <!-- Link femur_2 -->
      <body name="femur_2" pos="-1.08058e-17 -0.1137 0.0602" quat="0.707107 0.707107 1.22125e-15 -7.19866e-16">
        <!-- Joint from trunk to femur_2 -->
        <joint name="right_hip" type="hinge" range="-3.05433 3.05433"/>
        <inertial pos="-1.9262e-08 -0.142827 0.0596176" mass="0.7645" fullinertia="0.00377771 0.000940238 0.00358651 6.45614e-10 -5.25505e-10 0.000901135"/>
        <!-- Part qdd100_rotor_3 -->
        <geom type="mesh" class="visual" pos="0 6.93889e-18 -0.0287" quat="1 0 1.11022e-16 1.11022e-16" mesh="qdd100_rotor" material="qdd100_rotor_material"/>
        <!-- Part qdd100_support_2 -->
        <geom name="right_femur_collision1" class="collision" pos="-3.5027e-15 -0.17015 0.0557487" quat="4.91104e-17 -9.31589e-17 6.11189e-17 -1" type="cylinder" size="0.05 0.0125"/>
        <geom name="right_femur_collision2" class="collision" pos="-3.5027e-15 -0.17015 0.0252487" quat="0.5 -0.5 0.5 0.5" type="cylinder" size="0.02 0.03"/>
        <geom type="mesh" class="visual" pos="-3.5027e-15 -0.17015 0.0682487" quat="4.91104e-17 -9.31589e-17 6.11189e-17 -1" mesh="qdd100_support" material="qdd100_support_material"/>
        <!-- Part femur_2 -->
        <geom type="mesh" class="visual" pos="-4.58159e-15 -0.2 0.0261244" quat="0.5 -0.5 -0.5 -0.5" mesh="femur" material="femur_material"/>
        <!-- Part link_end_3 -->
        <geom name="right_femur_collision3" class="collision" pos="6.65206e-34 6.93889e-18 0.0247" quat="0.707107 0.707107 0 -2.23212e-32" type="cylinder" size="0.021 0.04"/>
        <geom type="mesh" class="visual" pos="0 6.93889e-18 -0.0287" quat="1 0 1.11022e-16 1.11022e-16" mesh="link_end" material="link_end_material"/>
        <!-- Part qdd100_stator_4 -->
        <geom name="right_femur_collision4" class="collision" pos="-3.5027e-15 -0.17015 0.0825987" quat="4.91104e-17 -9.31589e-17 6.11189e-17 -1" type="cylinder" size="0.05 0.01435"/>
        <geom type="mesh" class="visual" pos="-3.5027e-15 -0.17015 0.0682487" quat="4.91104e-17 -9.31589e-17 6.11189e-17 -1" mesh="qdd100_stator__2" material="qdd100_stator__2_material"/>
        <!-- Link tibia_2 -->
        <body name="tibia_2" pos="-3.5027e-15 -0.17015 0.0969487" quat="0 -1.89858e-17 -1 -5.35936e-17">
          <!-- Joint from femur_2 to tibia_2 -->
          <joint name="right_knee" type="hinge" range="-2.705260340591211 2.705260340591211"/>
          <inertial pos="-5.94135e-06 -0.117367 -0.00307405" mass="0.3865" fullinertia="0.00259272 0.000261473 0.00249172 -1.62499e-07 1.48913e-08 0.000309417"/>
          <!-- Part qdd100_rotor_4 -->
          <geom type="mesh" class="visual" pos="3.46945e-18 2.77556e-17 0.0287" quat="2.22045e-16 1.26281e-16 -1 -3.05311e-16" mesh="qdd100_rotor" material="qdd100_rotor_material"/>
          <!-- Part moteus_controller_2 -->
          <geom type="mesh" class="visual" pos="1.0995e-14 -0.1845 0.0046" quat="0.707107 -0.707107 -2.26485e-14 2.30815e-14" mesh="moteus_controller" material="moteus_controller_material"/>
          <!-- Part mj5208_stator_2 -->
          <geom type="mesh" class="visual" pos="1.15097e-14 -0.1765 0.012" quat="1 3.54647e-16 4.44089e-16 6.45595e-14" mesh="mj5208_stator" material="mj5208_stator_material"/>
          <!-- Part mj5208_support_2 -->
          <geom name="right_tibia_collision1" class="collision" pos="1.10011e-14 -0.17025 -0.02616" quat="0.707107 -0.707107 -2.26485e-14 2.30815e-14" type="cylinder" size="0.022 0.03025"/>
          <geom name="right_tibia_collision2" class="collision" pos="0.019 -0.17025 0.00774" quat="0.707107 -0.707107 -2.26485e-14 2.30815e-14" type="cylinder" size="0.021 0.03025"/>
          <geom name="right_tibia_collision3" class="collision" pos="-0.019 -0.17025 0.00774" quat="0.707107 -0.707107 -2.26485e-14 2.30815e-14" type="cylinder" size="0.021 0.03025"/>
          <geom type="mesh" class="visual" pos="1.14357e-14 -0.1765 0.03424" quat="0.707107 -0.707107 -2.26485e-14 2.30815e-14" mesh="mj5208_support" material="mj5208_support_material"/>
          <!-- Part tibia_2 -->
          <geom type="mesh" class="visual" pos="1.24225e-14 -0.2 -0.0261244" quat="0.5 -0.5 -0.5 -0.5" mesh="tibia" material="tibia_material"/>
          <!-- Part controller_bracket_2 -->
          <geom type="mesh" class="visual" pos="1.14357e-14 -0.1765 0.03424" quat="0.707107 -0.707107 -2.26485e-14 2.30815e-14" mesh="controller_bracket" material="controller_bracket_material"/>
          <!-- Part link_end_4 -->
          <geom name="right_tibia_collision4" class="collision" pos="-1.34196e-17 2.17975e-17 -0.0247" quat="1.11022e-16 -1.87573e-16 0.707107 -0.707107" type="cylinder" size="0.021 0.04"/>
          <geom type="mesh" class="visual" pos="3.46945e-18 2.77556e-17 0.0287" quat="2.22045e-16 1.26281e-16 -1 -3.05311e-16" mesh="link_end" material="link_end_material"/>
          <!-- Frame right_foot -->
          <site group="0" name="right_foot" pos="1.15189e-14 -0.1765 0.05095" quat="4.57273e-14 4.73882e-14 -0.707107 -0.707107"/>
          <!-- Link wheel_2 -->
          <body name="wheel_2" pos="1.15121e-14 -0.1765 0.0195" quat="1.52494e-16 -0.707107 0.707107 5.06061e-16">
            <!-- Joint from tibia_2 to wheel_2 -->
            <joint name="right_wheel"/>
            <inertial pos="-7.85066e-06 4.53426e-06 -0.0252368" mass="0.2585" fullinertia="0.000202065 0.000202069 0.000313606 -7.7265e-09 1.97562e-08 -1.14162e-08"/>
            <!-- Part wheel_hub_2 -->
            <geom type="mesh" class="visual" pos="-5.55112e-17 1.03827e-16 -0.0104" quat="0.707107 0.707107 0 -4.95236e-32" mesh="wheel_hub" material="wheel_hub_material"/>
            <!-- Part mj5208_rotor_2 -->
            <geom type="mesh" class="visual" pos="0 0 0.0075" quat="0 1 0 0" mesh="mj5208_rotor" material="mj5208_rotor_material"/>
            <!-- Part tire_2 -->
            <geom name="right_foot_collision" class="collision" pos="1.66533e-16 7.22077e-17 -0.0312" quat="0 1 0 0" type="cylinder" size="0.055 0.022"/>
            <geom type="mesh" class="visual" pos="1.66533e-16 7.22077e-17 -0.0312" quat="0.707107 0.707107 -0 -1.16514e-30" mesh="tire" material="tire_material"/>
          </body>
        </body>
      </body>
    </body>
  </worldbody>

  <asset>
    <mesh file="femur.stl"/>
    <mesh file="bottom_cover.stl"/>
    <mesh file="power_dist.stl"/>
    <mesh file="raspberry.stl"/>
    <mesh file="tire.stl"/>
    <mesh file="qdd100_stator__2.stl"/>
    <mesh file="mj5208_rotor.stl"/>
    <mesh file="back_opening.stl"/>
    <mesh file="switch.stl"/>
    <mesh file="top_cover.stl"/>
    <mesh file="separating_panel.stl"/>
    <mesh file="front_opening.stl"/>
    <mesh file="controller_bracket.stl"/>
    <mesh file="qdd100_support.stl"/>
    <mesh file="right_side.stl"/>
    <mesh file="qdd100_rotor.stl"/>
    <mesh file="mj5208_support.stl"/>
    <mesh file="front_cover.stl"/>
    <mesh file="wheel_hub.stl"/>
    <mesh file="back_cover.stl"/>
    <mesh file="moteus_controller.stl"/>
    <mesh file="left_side.stl"/>
    <mesh file="battery_tattu.stl"/>
    <mesh file="tibia.stl"/>
    <mesh file="link_end.stl"/>
    <mesh file="mj5208_stator.stl"/>
    <mesh file="qdd100_stator.stl"/>
    <material name="back_cover_material" rgba="0.513725 0.415686 0.733333 1"/>
    <material name="right_side_material" rgba="0.901961 0.901961 0.901961 1"/>
    <material name="separating_panel_material" rgba="0.768627 0.886275 0.952941 1"/>
    <material name="left_side_material" rgba="0.901961 0.901961 0.901961 1"/>
    <material name="top_cover_material" rgba="0.513725 0.415686 0.733333 1"/>
    <material name="power_dist_material" rgba="0.627451 0.627451 0.627451 1"/>
    <material name="bottom_cover_material" rgba="0.513725 0.415686 0.733333 1"/>
    <material name="switch_material" rgba="0.501961 0.501961 0.501961 1"/>
    <material name="front_opening_material" rgba="0.513725 0.415686 0.733333 1"/>
    <material name="qdd100_stator_material" rgba="0.196078 0.196078 0.196078 1"/>
    <material name="back_opening_material" rgba="0.513725 0.415686 0.733333 1"/>
    <material name="battery_tattu_material" rgba="0.701961 0.701961 0.701961 1"/>
    <material name="raspberry_material" rgba="0.627451 0.627451 0.627451 1"/>
    <material name="front_cover_material" rgba="0.513725 0.415686 0.733333 1"/>
    <material name="qdd100_rotor_material" rgba="0.196078 0.196078 0.196078 1"/>
    <material name="qdd100_support_material" rgba="0.513725 0.415686 0.733333 1"/>
    <material name="femur_material" rgba="0.901961 0.901961 0.901961 1"/>
    <material name="link_end_material" rgba="0.513725 0.415686 0.733333 1"/>
    <material name="qdd100_stator__2_material" rgba="0.196078 0.196078 0.196078 1"/>
    <material name="moteus_controller_material" rgba="0.909804 0.678431 0.137255 1"/>
    <material name="mj5208_stator_material" rgba="0.980392 0.713725 0.00392157 1"/>
    <material name="mj5208_support_material" rgba="0.513725 0.415686 0.733333 1"/>
    <material name="tibia_material" rgba="0.901961 0.901961 0.901961 1"/>
    <material name="controller_bracket_material" rgba="0.627451 0.627451 0.627451 1"/>
    <material name="wheel_hub_material" rgba="0.901961 0.901961 0.901961 1"/>
    <material name="mj5208_rotor_material" rgba="0.196078 0.196078 0.196078 1"/>
    <material name="tire_material" rgba="0.301961 0.301961 0.301961 1"/>
  </asset>
    
  <actuator>
    <position name="left_hip" joint="left_hip" kp="8" kv="0.1" forcerange="-16.0 16.0"/>
    <position name="left_knee" joint="left_knee" kp="8" kv="0.1" forcerange="-16.0 16.0"/>
    <velocity name="left_wheel" joint="left_wheel" kv="0.05" forcerange="-1.7 1.7"/>
    <position name="right_hip" joint="right_hip" kp="8" kv="0.1" forcerange="-16.0 16.0"/>
    <position name="right_knee" joint="right_knee" kp="8" kv="0.1" forcerange="-16.0 16.0"/>
    <velocity name="right_wheel" joint="right_wheel" kv="0.05" forcerange="-1.7 1.7"/>
  </actuator>

  <sensor>
    <framequat name="imu_quad" objtype="site" objname="imu" />
    <gyro name="imu_ang_vel" site="imu" />
    <velocimeter name="imu_lin_vel" site="imu" />
  </sensor>

  <equality/>
</mujoco>