<?xml version="1.0" ?>
<!-- Generated using onshape-to-robot -->
<!-- Onshape https://cad.onshape.com/documents/626c0feba56391e940274c5a/w/1443de40ca7efab6f3e18861/e/f40baedc39efd40637593503 -->

<mujoco model="upkie">
  <compiler angle="radian" meshdir="assets" autolimits="true"/>

  <default>
    <default class="upkie">
      <joint frictionloss="0.1" armature="0.005"/>
      <position dampratio="1"/>
      <default class="visual">
        <geom type="mesh" contype="0" conaffinity="0" group="2"/>
      </default>
      <default class="collision">
        <geom group="3"/>
      </default>
    </default>
  </default>

  <!-- Additional no_slip.xml -->
  <option noslip_iterations="4"/>
  
  <worldbody>
    <!-- Link trunk -->
    <body name="trunk" pos="0 0 0" quat="1 0 0 0" childclass="upkie">
      <freejoint name="trunk_freejoint"/>
      <inertial pos="0.181193 -0.0716052 -0.0581026" mass="2.6415" fullinertia="0.0127537 0.0217792 0.0147651 -6.48605e-05 -3.98875e-05 -0.000263842"/>
      <!-- Part back_cover -->
      <geom type="mesh" class="visual" pos="0.0955967 -0.0712693 -0.0206144" quat="1 7.72553e-09 -1.37021e-08 -4.73723e-09" mesh="back_cover" material="back_cover_material"/>
      <!-- Part right_side -->
      <geom type="mesh" class="visual" pos="0.0955967 -0.0714693 -0.0206144" quat="1 7.72553e-09 -1.37021e-08 -4.73723e-09" mesh="right_side" material="right_side_material"/>
      <!-- Part separating_panel -->
      <geom type="mesh" class="visual" pos="0.0955967 -0.0714693 -0.0210144" quat="1 7.72553e-09 -1.37021e-08 -4.73723e-09" mesh="separating_panel" material="separating_panel_material"/>
      <!-- Part left_side -->
      <geom type="mesh" class="visual" pos="0.0955967 -0.0714693 -0.0206144" quat="1 7.72553e-09 -1.37021e-08 -4.73723e-09" mesh="left_side" material="left_side_material"/>
      <!-- Part top_cover -->
      <geom type="mesh" class="visual" pos="0.0955967 -0.0714693 -0.0208144" quat="1 7.72553e-09 -1.37021e-08 -4.73723e-09" mesh="top_cover" material="top_cover_material"/>
      <!-- Part power_dist -->
      <geom type="mesh" class="visual" pos="0.150597 -0.0162693 -0.0205681" quat="8.8125e-09 -0.707107 -2.11305e-09 0.707107" mesh="power_dist" material="power_dist_material"/>
      <!-- Part bottom_cover -->
      <geom name="trunk_collision1" class="collision" pos="0.180597 -0.0714693 -0.0208144" quat="1 7.72553e-09 -1.37021e-08 -4.73723e-09" type="box" size="0.085 0.0652 0.125"/>
      <geom type="mesh" class="visual" pos="0.0955967 -0.0714693 -0.0208144" quat="1 7.72553e-09 -1.37021e-08 -4.73723e-09" mesh="bottom_cover" material="bottom_cover_material"/>
      <!-- Part switch -->
      <geom type="mesh" class="visual" pos="0.0955967 -0.0364693 0.0113856" quat="0.707107 2.11305e-09 -0.707107 -8.81251e-09" mesh="switch" material="switch_material"/>
      <!-- Part front_opening -->
      <geom type="mesh" class="visual" pos="0.0955967 -0.0714693 -0.0208144" quat="1 7.72553e-09 -1.37021e-08 -4.73723e-09" mesh="front_opening" material="front_opening_material"/>
      <!-- Part qdd100_stator -->
      <geom name="trunk_collision2" class="collision" pos="0.279947 -0.0714693 -0.0856144" quat="8.81251e-09 -0.707107 -2.11305e-09 0.707107" type="cylinder" size="0.05 0.01435"/>
      <geom type="mesh" class="visual" pos="0.265597 -0.0714693 -0.0206144" quat="4.73723e-09 -1.37021e-08 -7.72553e-09 1" mesh="qdd100_stator" material="qdd100_stator_material"/>
      <!-- Part back_opening -->
      <geom type="mesh" class="visual" pos="0.0955967 -0.0714693 -0.0208144" quat="1 7.72553e-09 -1.37021e-08 -4.73723e-09" mesh="back_opening" material="back_opening_material"/>
      <!-- Part qdd100_stator_2 -->
      <geom name="trunk_collision3" class="collision" pos="0.0812467 -0.0714693 -0.0856144" quat="0.707107 8.81251e-09 0.707107 2.11305e-09" type="cylinder" size="0.05 0.01435"/>
      <geom type="mesh" class="visual" pos="0.0955967 -0.0714693 -0.0206144" quat="1 7.72553e-09 -1.37021e-08 -4.73723e-09" mesh="qdd100_stator" material="qdd100_stator_material"/>
      <!-- Part battery_tattu -->
      <geom type="mesh" class="visual" pos="0.158097 -0.0824693 -0.0710144" quat="0.5 0.5 0.5 0.5" mesh="battery_tattu" material="battery_tattu_material"/>
      <!-- Part raspberry -->
      <geom type="mesh" class="visual" pos="0.220598 -0.0297693 -0.0130683" quat="4.73724e-09 -1.37021e-08 -7.72554e-09 1" mesh="raspberry" material="raspberry_material"/>
      <!-- Part front_cover -->
      <geom type="mesh" class="visual" pos="0.0955967 -0.0716693 -0.0206144" quat="1 7.72553e-09 -1.37021e-08 -4.73723e-09" mesh="front_cover" material="front_cover_material"/>
      <!-- Frame body -->
      <site group="0" name="body" pos="0.180597 -0.0714693 -0.145814" quat="0.707107 1.51516e-08 -4.22609e-09 -0.707107"/>
      <!-- Frame imu -->
      <site group="0" name="imu" pos="0.220598 -0.0305193 -0.0155683" quat="6.33914e-09 1.30386e-08 0.707107 -0.707107"/>
      <!-- Link femur -->
      <body name="femur" pos="0.294297 -0.0714693 -0.0856144" quat="0.5 0.5 0.5 0.5">
        <!-- Joint from trunk to femur -->
        <joint name="left_hip" type="hinge" range="-2.6179938779914944 2.6179938779914944"/>
        <inertial pos="-1.9262e-08 -0.142827 0.0596176" mass="0.7645" fullinertia="0.00377771 0.000940238 0.00358651 6.45614e-10 -5.25505e-10 0.000901135"/>
        <!-- Part qdd100_rotor -->
        <geom type="mesh" class="visual" pos="0 1.38778e-17 -0.0287" quat="1 0 -1.11022e-16 5.55112e-17" mesh="qdd100_rotor" material="qdd100_rotor_material"/>
        <!-- Part qdd100_support -->
        <geom name="left_femur_collision1" class="collision" pos="-1.94289e-16 -0.17015 0.0557487" quat="4.16334e-17 -0 8.32667e-17 1" type="cylinder" size="0.05 0.0125"/>
        <geom name="left_femur_collision2" class="collision" pos="-1.94289e-16 -0.17015 0.0252487" quat="0.5 -0.5 0.5 0.5" type="cylinder" size="0.02 0.03"/>
        <geom type="mesh" class="visual" pos="-1.94289e-16 -0.17015 0.0682487" quat="4.16334e-17 -0 8.32667e-17 1" mesh="qdd100_support" material="qdd100_support_material"/>
        <!-- Part femur -->
        <geom type="mesh" class="visual" pos="3.747e-16 -0.2 0.0261244" quat="0.5 -0.5 -0.5 -0.5" mesh="femur" material="femur_material"/>
        <!-- Part link_end -->
        <geom name="left_femur_collision3" class="collision" pos="2.79702e-26 1.38778e-17 0.0247" quat="0.707107 0.707107 -0 7.83011e-25" type="cylinder" size="0.021 0.04"/>
        <geom type="mesh" class="visual" pos="0 1.38778e-17 -0.0287" quat="1 0 -1.11022e-16 5.55112e-17" mesh="link_end" material="link_end_material"/>
        <!-- Part qdd100_stator_3 -->
        <geom name="left_femur_collision4" class="collision" pos="-1.94289e-16 -0.17015 0.0825987" quat="4.16334e-17 -0 8.32667e-17 1" type="cylinder" size="0.05 0.01435"/>
        <geom type="mesh" class="visual" pos="-1.94289e-16 -0.17015 0.0682487" quat="4.16334e-17 -0 8.32667e-17 1" mesh="qdd100_stator__2" material="qdd100_stator__2_material"/>
        <!-- Link tibia -->
        <body name="tibia" pos="-1.94289e-16 -0.17015 0.0969487" quat="2.22045e-16 -0 -1 2.77556e-16">
          <!-- Joint from femur to tibia -->
          <joint name="left_knee" type="hinge" range="-2.6179938779914935 2.6179938779914953"/>
          <inertial pos="-5.94135e-06 -0.117367 -0.00307405" mass="0.3865" fullinertia="0.00259272 0.000261473 0.00249172 -1.62499e-07 1.48913e-08 0.000309417"/>
          <!-- Part qdd100_rotor_2 -->
          <geom type="mesh" class="visual" pos="-4.16334e-17 0 0.0287" quat="5.55112e-16 6.941e-17 1 0" mesh="qdd100_rotor" material="qdd100_rotor_material"/>
          <!-- Part moteus_controller -->
          <geom type="mesh" class="visual" pos="1.30035e-14 -0.1845 0.0046" quat="0.707107 -0.707107 -2.26485e-14 2.26673e-14" mesh="moteus_controller" material="moteus_controller_material"/>
          <!-- Part mj5208_stator -->
          <geom type="mesh" class="visual" pos="1.17822e-14 -0.1765 0.012" quat="1 -1.09558e-16 -3.33067e-16 2.22045e-16" mesh="mj5208_stator" material="mj5208_stator_material"/>
          <!-- Part mj5208_support -->
          <geom name="left_tibia_collision1" class="collision" pos="1.13787e-14 -0.17025 -0.02616" quat="0.707107 -0.707107 -2.26485e-14 2.26673e-14" type="cylinder" size="0.022 0.03025"/>
          <geom name="left_tibia_collision2" class="collision" pos="0.019 -0.17025 0.00774" quat="0.707107 -0.707107 -2.26485e-14 2.26673e-14" type="cylinder" size="0.021 0.03025"/>
          <geom name="left_tibia_collision3" class="collision" pos="-0.019 -0.17025 0.00774" quat="0.707107 -0.707107 -2.26485e-14 2.26673e-14" type="cylinder" size="0.021 0.03025"/>
          <geom type="mesh" class="visual" pos="1.17822e-14 -0.1765 0.03424" quat="0.707107 -0.707107 -2.26485e-14 2.26673e-14" mesh="mj5208_support" material="mj5208_support_material"/>
          <!-- Part tibia -->
          <geom type="mesh" class="visual" pos="1.34337e-14 -0.2 -0.0261244" quat="0.5 -0.5 -0.5 -0.5" mesh="tibia" material="tibia_material"/>
          <!-- Part controller_bracket -->
          <geom type="mesh" class="visual" pos="1.17822e-14 -0.1765 0.03424" quat="0.707107 -0.707107 -2.26485e-14 2.26673e-14" mesh="controller_bracket" material="controller_bracket_material"/>
          <!-- Part link_end_2 -->
          <geom name="left_tibia_collision4" class="collision" pos="2.96789e-18 -2.94866e-17 -0.0247" quat="0 2.96794e-16 0.707107 -0.707107" type="cylinder" size="0.021 0.04"/>
          <geom type="mesh" class="visual" pos="-4.16334e-17 0 0.0287" quat="5.55112e-16 6.941e-17 1 0" mesh="link_end" material="link_end_material"/>
          <!-- Frame left_foot -->
          <site group="0" name="left_foot" pos="1.17545e-14 -0.1765 0.05095" quat="0.707107 -0.707107 -0 1.67713e-15"/>
          <!-- Link wheel -->
          <body name="wheel" pos="1.17822e-14 -0.1765 0.0195" quat="2.77288e-16 -0.707107 0.707107 -3.40905e-16">
            <!-- Joint from tibia to wheel -->
            <joint name="left_wheel"/>
            <inertial pos="-7.85066e-06 4.53426e-06 -0.0252368" mass="0.2585" fullinertia="0.000202065 0.000202069 0.000313606 -7.7265e-09 1.97562e-08 -1.14162e-08"/>
            <!-- Part wheel_hub -->
            <geom type="mesh" class="visual" pos="3.88578e-16 -2.77556e-17 -0.0104" quat="0.707107 0.707107 0 2.94392e-17" mesh="wheel_hub" material="wheel_hub_material"/>
            <!-- Part mj5208_rotor -->
            <geom type="mesh" class="visual" pos="0 1.38778e-17 0.0075" quat="0 1 0 0" mesh="mj5208_rotor" material="mj5208_rotor_material"/>
            <!-- Part tire -->
            <geom name="left_foot_collision" class="collision" pos="4.996e-16 2.77556e-17 -0.0312" quat="0.707107 0.707107 0 2.94392e-17" type="sphere" size="0.056"/>
            <geom type="mesh" class="visual" pos="4.996e-16 2.77556e-17 -0.0312" quat="0.707107 0.707107 0 2.94392e-17" mesh="tire" material="tire_material"/>
          </body>
        </body>
      </body>
      <!-- Link femur_2 -->
      <body name="femur_2" pos="0.0668967 -0.0714693 -0.0856144" quat="0.5 0.5 -0.5 -0.5">
        <!-- Joint from trunk to femur_2 -->
        <joint name="right_hip" type="hinge" range="-2.617993893442557 2.6179938625404318"/>
        <inertial pos="-1.9262e-08 -0.142827 0.0596176" mass="0.7645" fullinertia="0.00377771 0.000940238 0.00358651 6.45614e-10 -5.25505e-10 0.000901135"/>
        <!-- Part qdd100_rotor_3 -->
        <geom type="mesh" class="visual" pos="-1.38778e-17 1.38778e-17 -0.0287" quat="1 -0 -1.11022e-16 -1.38778e-17" mesh="qdd100_rotor" material="qdd100_rotor_material"/>
        <!-- Part qdd100_support_2 -->
        <geom name="right_femur_collision1" class="collision" pos="2.91434e-16 -0.17015 0.0557487" quat="0 0 -1.11022e-16 -1" type="cylinder" size="0.05 0.0125"/>
        <geom name="right_femur_collision2" class="collision" pos="2.91434e-16 -0.17015 0.0252487" quat="0.5 -0.5 0.5 0.5" type="cylinder" size="0.02 0.03"/>
        <geom type="mesh" class="visual" pos="2.91434e-16 -0.17015 0.0682487" quat="0 0 -1.11022e-16 -1" mesh="qdd100_support" material="qdd100_support_material"/>
        <!-- Part femur_2 -->
        <geom type="mesh" class="visual" pos="-6.93889e-17 -0.2 0.0261244" quat="0.5 -0.5 -0.5 -0.5" mesh="femur" material="femur_material"/>
        <!-- Part link_end_3 -->
        <geom name="right_femur_collision3" class="collision" pos="-1.38778e-17 1.38778e-17 0.0247" quat="0.707107 0.707107 -0 1.10411e-25" type="cylinder" size="0.021 0.04"/>
        <geom type="mesh" class="visual" pos="-1.38778e-17 1.38778e-17 -0.0287" quat="1 -0 -1.11022e-16 -1.38778e-17" mesh="link_end" material="link_end_material"/>
        <!-- Part qdd100_stator_4 -->
        <geom name="right_femur_collision4" class="collision" pos="2.91434e-16 -0.17015 0.0825987" quat="0 0 -1.11022e-16 -1" type="cylinder" size="0.05 0.01435"/>
        <geom type="mesh" class="visual" pos="2.91434e-16 -0.17015 0.0682487" quat="0 0 -1.11022e-16 -1" mesh="qdd100_stator__2" material="qdd100_stator__2_material"/>
        <!-- Link tibia_2 -->
        <body name="tibia_2" pos="2.91434e-16 -0.17015 0.0969487" quat="1.11022e-16 0 -1 0">
          <!-- Joint from femur_2 to tibia_2 -->
          <joint name="right_knee" type="hinge" range="-2.617993877991474 2.617993877991515"/>
          <inertial pos="-5.94135e-06 -0.117367 -0.00307405" mass="0.3865" fullinertia="0.00259272 0.000261473 0.00249172 -1.62499e-07 1.48913e-08 0.000309417"/>
          <!-- Part qdd100_rotor_4 -->
          <geom type="mesh" class="visual" pos="2.77556e-17 5.55112e-17 0.0287" quat="1.40513e-16 -1.00475e-14 -1 -1.05818e-16" mesh="qdd100_rotor" material="qdd100_rotor_material"/>
          <!-- Part moteus_controller_2 -->
          <geom type="mesh" class="visual" pos="7.29972e-15 -0.1845 0.0046" quat="0.707107 -0.707107 -1.54321e-14 1.58648e-14" mesh="moteus_controller" material="moteus_controller_material"/>
          <!-- Part mj5208_stator_2 -->
          <geom type="mesh" class="visual" pos="7.89646e-15 -0.1765 0.012" quat="1 3.3196e-16 -0 5.42899e-14" mesh="mj5208_stator" material="mj5208_stator_material"/>
          <!-- Part mj5208_support_2 -->
          <geom name="right_tibia_collision1" class="collision" pos="7.56319e-15 -0.17025 -0.02616" quat="0.707107 -0.707107 -1.54321e-14 1.58648e-14" type="cylinder" size="0.022 0.03025"/>
          <geom name="right_tibia_collision2" class="collision" pos="0.019 -0.17025 0.00774" quat="0.707107 -0.707107 -1.54321e-14 1.58648e-14" type="cylinder" size="0.021 0.03025"/>
          <geom name="right_tibia_collision3" class="collision" pos="-0.019 -0.17025 0.00774" quat="0.707107 -0.707107 -1.54321e-14 1.58648e-14" type="cylinder" size="0.021 0.03025"/>
          <geom type="mesh" class="visual" pos="7.88258e-15 -0.1765 0.03424" quat="0.707107 -0.707107 -1.54321e-14 1.58648e-14" mesh="mj5208_support" material="mj5208_support_material"/>
          <!-- Part tibia_2 -->
          <geom type="mesh" class="visual" pos="8.34055e-15 -0.2 -0.0261244" quat="0.5 -0.5 -0.5 -0.5" mesh="tibia" material="tibia_material"/>
          <!-- Part controller_bracket_2 -->
          <geom type="mesh" class="visual" pos="7.88258e-15 -0.1765 0.03424" quat="0.707107 -0.707107 -1.54321e-14 1.58648e-14" mesh="controller_bracket" material="controller_bracket_material"/>
          <!-- Part link_end_4 -->
          <geom name="right_tibia_collision4" class="collision" pos="7.71405e-19 5.55112e-17 -0.0247" quat="7.21645e-15 -7.04139e-15 -0.707107 0.707107" type="cylinder" size="0.021 0.04"/>
          <geom type="mesh" class="visual" pos="2.77556e-17 5.55112e-17 0.0287" quat="1.40513e-16 -1.00475e-14 -1 -1.05818e-16" mesh="link_end" material="link_end_material"/>
          <!-- Frame right_foot -->
          <site group="0" name="right_foot" pos="7.92422e-15 -0.1765 0.05095" quat="3.84415e-14 4.01127e-14 -0.707107 -0.707107"/>
          <!-- Link wheel_2 -->
          <body name="wheel_2" pos="7.91034e-15 -0.1765 0.0195" quat="1.39521e-16 -0.707107 0.707107 4.91111e-16">
            <!-- Joint from tibia_2 to wheel_2 -->
            <joint name="right_wheel"/>
            <inertial pos="-7.85066e-06 4.53426e-06 -0.0252368" mass="0.2585" fullinertia="0.000202065 0.000202069 0.000313606 -7.7265e-09 1.97562e-08 -1.14162e-08"/>
            <!-- Part wheel_hub_2 -->
            <geom type="mesh" class="visual" pos="-5.55112e-17 2.77556e-17 -0.0104" quat="0.707107 0.707107 0 1.26394e-24" mesh="wheel_hub" material="wheel_hub_material"/>
            <!-- Part mj5208_rotor_2 -->
            <geom type="mesh" class="visual" pos="0 1.38778e-17 0.0075" quat="0 1 0 0" mesh="mj5208_rotor" material="mj5208_rotor_material"/>
            <!-- Part tire_2 -->
            <geom name="right_foot_collision" class="collision" pos="1.11022e-16 4.16334e-17 -0.0312" quat="0.707107 0.707107 -0 1.26394e-24" type="sphere" size="0.056"/>
            <geom type="mesh" class="visual" pos="1.11022e-16 4.16334e-17 -0.0312" quat="0.707107 0.707107 -0 1.26394e-24" mesh="tire" material="tire_material"/>
          </body>
        </body>
      </body>
    </body>
  </worldbody>

  <asset>
    <mesh file="qdd100_stator.stl"/>
    <mesh file="back_opening.stl"/>
    <mesh file="tibia.stl"/>
    <mesh file="separating_panel.stl"/>
    <mesh file="qdd100_support.stl"/>
    <mesh file="right_side.stl"/>
    <mesh file="front_cover.stl"/>
    <mesh file="qdd100_stator__2.stl"/>
    <mesh file="qdd100_rotor.stl"/>
    <mesh file="left_side.stl"/>
    <mesh file="controller_bracket.stl"/>
    <mesh file="femur.stl"/>
    <mesh file="front_opening.stl"/>
    <mesh file="raspberry.stl"/>
    <mesh file="top_cover.stl"/>
    <mesh file="back_cover.stl"/>
    <mesh file="tire.stl"/>
    <mesh file="wheel_hub.stl"/>
    <mesh file="link_end.stl"/>
    <mesh file="mj5208_rotor.stl"/>
    <mesh file="switch.stl"/>
    <mesh file="battery_tattu.stl"/>
    <mesh file="bottom_cover.stl"/>
    <mesh file="mj5208_stator.stl"/>
    <mesh file="mj5208_support.stl"/>
    <mesh file="power_dist.stl"/>
    <mesh file="moteus_controller.stl"/>
    <material name="back_cover_material" rgba="0.513725 0.415686 0.733333 1"/>
    <material name="right_side_material" rgba="0.901961 0.901961 0.901961 1"/>
    <material name="separating_panel_material" rgba="0.768627 0.886275 0.952941 1"/>
    <material name="left_side_material" rgba="0.901961 0.901961 0.901961 1"/>
    <material name="top_cover_material" rgba="0.513725 0.415686 0.733333 1"/>
    <material name="power_dist_material" rgba="0.627451 0.627451 0.627451 1"/>
    <material name="bottom_cover_material" rgba="0.513725 0.415686 0.733333 1"/>
    <material name="switch_material" rgba="0.501961 0.501961 0.501961 1"/>
    <material name="front_opening_material" rgba="0.513725 0.415686 0.733333 1"/>
    <material name="qdd100_stator_material" rgba="0.196078 0.196078 0.196078 1"/>
    <material name="back_opening_material" rgba="0.513725 0.415686 0.733333 1"/>
    <material name="battery_tattu_material" rgba="0.701961 0.701961 0.701961 1"/>
    <material name="raspberry_material" rgba="0.627451 0.627451 0.627451 1"/>
    <material name="front_cover_material" rgba="0.513725 0.415686 0.733333 1"/>
    <material name="qdd100_rotor_material" rgba="0.196078 0.196078 0.196078 1"/>
    <material name="qdd100_support_material" rgba="0.513725 0.415686 0.733333 1"/>
    <material name="femur_material" rgba="0.901961 0.901961 0.901961 1"/>
    <material name="link_end_material" rgba="0.513725 0.415686 0.733333 1"/>
    <material name="qdd100_stator__2_material" rgba="0.196078 0.196078 0.196078 1"/>
    <material name="moteus_controller_material" rgba="0.909804 0.678431 0.137255 1"/>
    <material name="mj5208_stator_material" rgba="0.980392 0.713725 0.00392157 1"/>
    <material name="mj5208_support_material" rgba="0.513725 0.415686 0.733333 1"/>
    <material name="tibia_material" rgba="0.901961 0.901961 0.901961 1"/>
    <material name="controller_bracket_material" rgba="0.627451 0.627451 0.627451 1"/>
    <material name="wheel_hub_material" rgba="0.901961 0.901961 0.901961 1"/>
    <material name="mj5208_rotor_material" rgba="0.196078 0.196078 0.196078 1"/>
    <material name="tire_material" rgba="0.301961 0.301961 0.301961 1"/>
  </asset>
  
  <actuator>
    <position name="left_hip" joint="left_hip" kp="3" kv="0.1" forcerange="-20.0 20.0"/>
    <position name="left_knee" joint="left_knee" kp="3" kv="0.1" forcerange="-20.0 20.0"/>
    <velocity name="left_wheel" joint="left_wheel" kv="5" forcerange="-10.0 10.0"/>
    <position name="right_hip" joint="right_hip" kp="3" kv="0.1" forcerange="-20.0 20.0"/>
    <position name="right_knee" joint="right_knee" kp="3" kv="0.1" forcerange="-20.0 20.0"/>
    <velocity name="right_wheel" joint="right_wheel" kv="5" forcerange="-10.0 10.0"/>
  </actuator>

  <sensor>
    <framequat name="imu_orientation" objtype="site" objname="imu" />
    <gyro name="imu_ang_vel" site="imu" />
    <velocimeter name="imu_lin_vel" site="imu" />
  </sensor>

  <equality/>
</mujoco>
